<?xml version="1.0" encoding="utf-8"?>
<!-- This URDF was automatically created by SolidWorks to URDF Exporter! Originally created by Stephen Brawner (brawner@gmail.com) 
     Commit Version: 1.6.0-4-g7f85cfe  Build Version: 1.6.7995.38578
     For more information, please see http://wiki.ros.org/sw_urdf_exporter -->
<robot
  name="scara_boxes">
  <link
    name="world_link">
    <inertial>
      <origin
        xyz="-0.379999991843833 -0.241999995946268 0.282642145469613"
        rpy="0 0 0" />
      <mass
        value="56.5143635061382" />
      <inertia
        ixx="3.10383758638064"
        ixy="9.38103874984808E-07"
        ixz="-4.5700988000864E-07"
        iyy="3.00109559506483"
        iyz="3.8993102369279E-08"
        izz="0.915005919197952" />
    </inertial>
    <visual>
      <origin
        xyz="0 0 0"
        rpy="0 0 0" />
      <geometry>
        <mesh
          filename="package://scara_boxes/meshes/world_link.STL" />
      </geometry>
      <material
        name="">
        <color
          rgba="0.792156862745098 0.819607843137255 0.933333333333333 1" />
      </material>
    </visual>
    <collision>
      <origin
        xyz="0 0 0"
        rpy="0 0 0" />
      <geometry>
        <mesh
          filename="package://scara_boxes/meshes/world_link.STL" />
      </geometry>
    </collision>
  </link>
  <link
    name="scara_link_base">
    <inertial>
      <origin
        xyz="4.11981024295294E-09 -0.00144952651535979 0.0824742549468586"
        rpy="0 0 0" />
      <mass
        value="10.0938987184175" />
      <inertia
        ixx="0.0864487528577416"
        ixy="-7.67600083954998E-08"
        ixz="-3.54288604352874E-09"
        iyy="0.0762174394798054"
        iyz="0.000783155397267453"
        izz="0.100368960083761" />
    </inertial>
    <visual>
      <origin
        xyz="0 0 0"
        rpy="0 0 0" />
      <geometry>
        <mesh
          filename="package://scara_boxes/meshes/scara_link_base.STL" />
      </geometry>
      <material
        name="">
        <color
          rgba="0.792156862745098 0.819607843137255 0.933333333333333 1" />
      </material>
    </visual>
    <collision>
      <origin
        xyz="0 0 0"
        rpy="0 0 0" />
      <geometry>
        <mesh
          filename="package://scara_boxes/meshes/scara_link_base.STL" />
      </geometry>
    </collision>
  </link>
  <joint
    name="scara_joint_base"
    type="fixed">
    <origin
      xyz="-0.38 -0.242 0.650000000000001"
      rpy="0 0 0" />
    <parent
      link="world_link" />
    <child
      link="scara_link_base" />
    <axis
      xyz="0 0 0" />
  </joint>
  <link
    name="scara_link_1">
    <inertial>
      <origin
        xyz="0.0554575444614087 0.165564551542489 0.0275000000000013"
        rpy="0 0 0" />
      <mass
        value="3.3230838247481" />
      <inertia
        ixx="0.0576270026353464"
        ixy="-0.0171642772796708"
        ixz="-2.85240477777696E-18"
        iyy="0.0119905480517804"
        iyz="-7.7409692678262E-18"
        izz="0.0679421595859383" />
    </inertial>
    <visual>
      <origin
        xyz="0 0 0"
        rpy="0 0 0" />
      <geometry>
        <mesh
          filename="package://scara_boxes/meshes/scara_link_1.STL" />
      </geometry>
      <material
        name="">
        <color
          rgba="0.792156862745098 0.819607843137255 0.933333333333333 1" />
      </material>
    </visual>
    <collision>
      <origin
        xyz="0 0 0"
        rpy="0 0 0" />
      <geometry>
        <mesh
          filename="package://scara_boxes/meshes/scara_link_1.STL" />
      </geometry>
    </collision>
  </link>
  <joint
    name="scara_joint_1"
    type="revolute">
    <origin
      xyz="0 0.0620000000000001 0.185999999999999"
      rpy="0 0 0" />
    <parent
      link="scara_link_base" />
    <child
      link="scara_link_1" />
    <axis
      xyz="0 0 -1" />
    <limit
      lower="-3"
      upper="3"
      effort="0"
      velocity="0" />
  </joint>
  <link
    name="scara_link_2">
    <inertial>
      <origin
        xyz="0.0846237938758736 0.153636740232568 0.109919168493605"
        rpy="0 0 0" />
      <mass
        value="17.9237237949378" />
      <inertia
        ixx="0.486676041203974"
        ixy="-0.20205161891764"
        ixz="0.0238411475845364"
        iyy="0.231136918692326"
        iyz="0.043284241977989"
        izz="0.538887927908261" />
    </inertial>
    <visual>
      <origin
        xyz="0 0 0"
        rpy="0 0 0" />
      <geometry>
        <mesh
          filename="package://scara_boxes/meshes/scara_link_2.STL" />
      </geometry>
      <material
        name="">
        <color
          rgba="0.792156862745098 0.819607843137255 0.933333333333333 1" />
      </material>
    </visual>
    <collision>
      <origin
        xyz="0 0 0"
        rpy="0 0 0" />
      <geometry>
        <mesh
          filename="package://scara_boxes/meshes/scara_link_2.STL" />
      </geometry>
    </collision>
  </link>
  <joint
    name="scara_joint_2"
    type="revolute">
    <origin
      xyz="0.110915088922802 0.331544853874762 0.0550000000000013"
      rpy="0 0 0" />
    <parent
      link="scara_link_1" />
    <child
      link="scara_link_2" />
    <axis
      xyz="0 0 -1" />
    <limit
      lower="-3"
      upper="3"
      effort="0"
      velocity="0" />
  </joint>
  <link
    name="scara_link_3">
    <inertial>
      <origin
        xyz="-5.48198860028659E-07 3.08047934466371E-07 -0.191819389863616"
        rpy="0 0 0" />
      <mass
        value="1.09878914470562" />
      <inertia
        ixx="0.0202026345558292"
        ixy="1.46163302702154E-08"
        ixz="-2.9902926720251E-09"
        iyy="0.0202026586253473"
        iyz="5.4617905886984E-09"
        izz="0.000398979796591897" />
    </inertial>
    <visual>
      <origin
        xyz="0 0 0"
        rpy="0 0 0" />
      <geometry>
        <mesh
          filename="package://scara_boxes/meshes/scara_link_3.STL" />
      </geometry>
      <material
        name="">
        <color
          rgba="0.792156862745098 0.819607843137255 0.933333333333333 1" />
      </material>
    </visual>
    <collision>
      <origin
        xyz="0 0 0"
        rpy="0 0 0" />
      <geometry>
        <mesh
          filename="package://scara_boxes/meshes/scara_link_3.STL" />
      </geometry>
    </collision>
  </link>
  <joint
    name="scara_joint_3"
    type="prismatic">
    <origin
      xyz="0.217106821845308 0.394163199586465 0"
      rpy="3.14159265358979 0 -3.14159265358979" />
    <parent
      link="scara_link_2" />
    <child
      link="scara_link_3" />
    <axis
      xyz="0 0 -1" />
    <limit
      lower="-0.05"
      upper="0"
      effort="0"
      velocity="0" />
  </joint>
  <link
    name="boxes">
    <inertial>
      <origin
        xyz="0.360011118600684 0.27521364223783 0.278912194799361"
        rpy="0 0 0" />
      <mass
        value="99.0267308175771" />
      <inertia
        ixx="3.36896676113991"
        ixy="7.18898606721354E-11"
        ixz="-1.42061685292634E-06"
        iyy="3.36911900381237"
        iyz="-6.3075170410186E-09"
        izz="0.678298179608551" />
    </inertial>
    <visual>
      <origin
        xyz="0 0 0"
        rpy="0 0 0" />
      <geometry>
        <mesh
          filename="package://scara_boxes/meshes/boxes.STL" />
      </geometry>
      <material
        name="">
        <color
          rgba="0.792156862745098 0.819607843137255 0.933333333333333 1" />
      </material>
    </visual>
    <collision>
      <origin
        xyz="0 0 0"
        rpy="0 0 0" />
      <geometry>
        <mesh
          filename="package://scara_boxes/meshes/boxes.STL" />
      </geometry>
    </collision>
  </link>
  <joint
    name="boxes"
    type="fixed">
    <origin
      xyz="-0.719999999999999 0 0"
      rpy="0 0 0" />
    <parent
      link="world_link" />
    <child
      link="boxes" />
    <axis
      xyz="0 0 0" />
  </joint>
</robot>