<?xml version="1.0" encoding="utf-8"?>
<!-- This URDF was automatically created by SolidWorks to URDF Exporter! Originally created by Stephen Brawner (brawner@gmail.com) 
     Commit Version: 1.6.0-4-g7f85cfe  Build Version: 1.6.7995.38578
     For more information, please see http://wiki.ros.org/sw_urdf_exporter -->
<robot
  name="scara">
  <link
    name="base_link">
    <inertial>
      <origin
        xyz="0 0 0"
        rpy="0 0 0" />
      <mass
        value="3.77817160684553" />
      <inertia
        ixx="0.0125308515250432"
        ixy="-0.00445886583451945"
        ixz="1.09656845989623E-10"
        iyy="0.0286083752580722"
        iyz="-1.19084940381239E-09"
        izz="0.0288757056713447" />
    </inertial>
    <visual>
      <origin
        xyz="0 0 0"
        rpy="0 0 0" />
      <geometry>
        <mesh
          filename="package://scara/meshes/base_link.STL" />
      </geometry>
      <material
        name="">
        <color
          rgba="0.792156862745098 0.819607843137255 0.933333333333333 1" />
      </material>
    </visual>
    <collision>
      <origin
        xyz="0 0 0"
        rpy="0 0 0" />
      <geometry>
        <mesh
          filename="package://scara/meshes/base_link.STL" />
      </geometry>
    </collision>
  </link>
  <link
    name="l1">
    <inertial>
      <origin
        xyz="0.100580298915214 0.0863670807289593 0.0800000017245166"
        rpy="0 0 0" />
      <mass
        value="3.77817160684553" />
      <inertia
        ixx="0.0125308515250432"
        ixy="-0.00445886583451945"
        ixz="1.09656845923179E-10"
        iyy="0.0286083752580722"
        iyz="-1.19084940380642E-09"
        izz="0.0288757056713447" />
    </inertial>
    <visual>
      <origin
        xyz="0 0 0"
        rpy="0 0 0" />
      <geometry>
        <mesh
          filename="package://scara/meshes/l1.STL" />
      </geometry>
      <material
        name="">
        <color
          rgba="0.792156862745098 0.819607843137255 0.933333333333333 1" />
      </material>
    </visual>
    <collision>
      <origin
        xyz="0 0 0"
        rpy="0 0 0" />
      <geometry>
        <mesh
          filename="package://scara/meshes/l1.STL" />
      </geometry>
    </collision>
  </link>
  <joint
    name="l1"
    type="fixed">
    <origin
      xyz="-0.075797 -1.07 -0.21267"
      rpy="1.5708 0 0" />
    <parent
      link="base_link" />
    <child
      link="l1" />
    <axis
      xyz="0 0 0" />
  </joint>
  <link
    name="j2">
    <inertial>
      <origin
        xyz="0.158848366931551 0.0366603336954162 -9.85374284390161E-08"
        rpy="0 0 0" />
      <mass
        value="2.9382548842988" />
      <inertia
        ixx="0.00547804648524969"
        ixy="-0.00214046701062641"
        ixz="5.09955047757558E-08"
        iyy="0.0516754027736658"
        iyz="1.89907468050839E-08"
        izz="0.0494511186006761" />
    </inertial>
    <visual>
      <origin
        xyz="0 0 0"
        rpy="0 0 0" />
      <geometry>
        <mesh
          filename="package://scara/meshes/j2.STL" />
      </geometry>
      <material
        name="">
        <color
          rgba="0.792156862745098 0.819607843137255 0.933333333333333 1" />
      </material>
    </visual>
    <collision>
      <origin
        xyz="0 0 0"
        rpy="0 0 0" />
      <geometry>
        <mesh
          filename="package://scara/meshes/j2.STL" />
      </geometry>
    </collision>
  </link>
  <joint
    name="j2"
    type="continuous">
    <origin
      xyz="0.46645 0.09 -0.042465"
      rpy="0 0.51939 0" />
    <parent
      link="l1" />
    <child
      link="j2" />
    <axis
      xyz="0 1 0" />
  </joint>
</robot>