<?xml version="1.0" encoding="utf-8" ?>
<!-- This URDF was automatically created by SolidWorks to URDF Exporter! Originally created by Stephen Brawner (brawner@gmail.com) 
     Commit Version: 1.6.0-4-g7f85cfe  Build Version: 1.6.7995.38578
     For more information, please see http://wiki.ros.org/sw_urdf_exporter -->
<robot name="fertig">
    <link name="world_link">
        <inertial>
            <origin xyz="-0.379999991843833 -0.241999995946268 0.282642145469613" rpy="0 0 0" />
            <mass value="56.5143635061382" />
            <inertia ixx="3.10383758638064" ixy="9.38103874984791E-07" ixz="-4.57009880018047E-07" iyy="3.00109559506483" iyz="3.89931023738117E-08" izz="0.915005919197952" />
        </inertial>
        <visual>
            <origin xyz="0 0 0" rpy="0 0 0" />
            <geometry>
                <mesh filename="package://fertig/meshes/world_link.STL" />
            </geometry>
            <material name="">
                <color rgba="0.792156862745098 0.819607843137255 0.933333333333333 1" />
            </material>
        </visual>
        <collision>
            <origin xyz="0 0 0" rpy="0 0 0" />
            <geometry>
                <mesh filename="package://fertig/meshes/world_link.STL" />
            </geometry>
        </collision>
    </link>
    <link name="scara_link_base">
        <inertial>
            <origin xyz="4.11981024295294E-09 -0.00144952651535979 0.0824742549468586" rpy="0 0 0" />
            <mass value="10.0938987184175" />
            <inertia ixx="0.0864487528577416" ixy="-7.67600083955194E-08" ixz="-3.54288604367275E-09" iyy="0.0762174394798054" iyz="0.000783155397267453" izz="0.100368960083761" />
        </inertial>
        <visual>
            <origin xyz="0 0 0" rpy="0 0 0" />
            <geometry>
                <mesh filename="package://fertig/meshes/scara_link_base.STL" />
            </geometry>
            <material name="">
                <color rgba="0.792156862745098 0.819607843137255 0.933333333333333 1" />
            </material>
        </visual>
        <collision>
            <origin xyz="0 0 0" rpy="0 0 0" />
            <geometry>
                <mesh filename="package://fertig/meshes/scara_link_base.STL" />
            </geometry>
        </collision>
    </link>
    <joint name="scara_joint_base" type="fixed">
        <origin xyz="-0.38 -0.242 0.650000000000001" rpy="0 0 0" />
        <parent link="world_link" />
        <child link="scara_link_base" />
        <axis xyz="0 0 0" />
    </joint>
    <link name="scara_link_1">
        <inertial>
            <origin xyz="0.0554575444614114 0.165564551542479 0.0275000000000013" rpy="0 0 0" />
            <mass value="3.3230838247481" />
            <inertia ixx="0.0576270026353464" ixy="-0.0171642772796708" ixz="-2.75711369663395E-18" iyy="0.0119905480517804" iyz="-7.73107852038133E-18" izz="0.0679421595859383" />
        </inertial>
        <visual>
            <origin xyz="0 0 0" rpy="0 0 0" />
            <geometry>
                <mesh filename="package://fertig/meshes/scara_link_1.STL" />
            </geometry>
            <material name="">
                <color rgba="0.792156862745098 0.819607843137255 0.933333333333333 1" />
            </material>
        </visual>
        <collision>
            <origin xyz="0 0 0" rpy="0 0 0" />
            <geometry>
                <mesh filename="package://fertig/meshes/scara_link_1.STL" />
            </geometry>
        </collision>
    </link>
    <joint name="scara_joint_1" type="revolute">
        <origin xyz="0 0.062 0.186" rpy="0 0 0" />
        <parent link="scara_link_base" />
        <child link="scara_link_1" />
        <axis xyz="0 0 -1" />
        <limit lower="-2.5" upper="2.5" effort="0" velocity="0" />
    </joint>
    <link name="scara_link_2">
        <inertial>
            <origin xyz="0.084623793875894 0.153636740232548 0.109919168493605" rpy="0 0 0" />
            <mass value="17.9237237949378" />
            <inertia ixx="0.486676041203974" ixy="-0.20205161891764" ixz="0.0238411475845364" iyy="0.231136918692326" iyz="0.043284241977989" izz="0.538887927908261" />
        </inertial>
        <visual>
            <origin xyz="0 0 0" rpy="0 0 0" />
            <geometry>
                <mesh filename="package://fertig/meshes/scara_link_2.STL" />
            </geometry>
            <material name="">
                <color rgba="0.792156862745098 0.819607843137255 0.933333333333333 1" />
            </material>
        </visual>
        <collision>
            <origin xyz="0 0 0" rpy="0 0 0" />
            <geometry>
                <mesh filename="package://fertig/meshes/scara_link_2.STL" />
            </geometry>
        </collision>
    </link>
    <joint name="scara_joint_2" type="revolute">
        <origin xyz="0.11092 0.33154 0.055" rpy="0 0 0" />
        <parent link="scara_link_1" />
        <child link="scara_link_2" />
        <axis xyz="0 0 -1" />
        <limit lower="-2.5" upper="2.5" effort="0" velocity="0" />
    </joint>
    <link name="scara_link_3">
        <inertial>
            <origin xyz="-5.48198860028659E-07 3.08047934466371E-07 -0.191819389863616" rpy="0 0 0" />
            <mass value="1.09878914470562" />
            <inertia ixx="0.0202026345558292" ixy="1.46163302702154E-08" ixz="-2.9902926720251E-09" iyy="0.0202026586253473" iyz="5.4617905886984E-09" izz="0.000398979796591897" />
        </inertial>
        <visual>
            <origin xyz="0 0 0" rpy="0 0 0" />
            <geometry>
                <mesh filename="package://fertig/meshes/scara_link_3.STL" />
            </geometry>
            <material name="">
                <color rgba="0.792156862745098 0.819607843137255 0.933333333333333 1" />
            </material>
        </visual>
        <collision>
            <origin xyz="0 0 0" rpy="0 0 0" />
            <geometry>
                <mesh filename="package://fertig/meshes/scara_link_3.STL" />
            </geometry>
        </collision>
    </link>
    <joint name="scara_joint_3" type="prismatic">
        <origin xyz="0.21711 0.39416 0" rpy="3.1416 0 -3.1416" />
        <parent link="scara_link_2" />
        <child link="scara_link_3" />
        <axis xyz="0 0 -1" />
        <limit lower="-2.5" upper="2.5" effort="0" velocity="0" />
    </joint>
    <link name="boxes">
        <inertial>
            <origin xyz="0.360011118600685 0.27521364223783 0.278912194799361" rpy="0 0 0" />
            <mass value="99.0267308175771" />
            <inertia ixx="3.36896676113991" ixy="7.18898608773253E-11" ixz="-1.42061685292724E-06" iyy="3.36911900381237" iyz="-6.30751704044779E-09" izz="0.678298179608551" />
        </inertial>
        <visual>
            <origin xyz="0 0 0" rpy="0 0 0" />
            <geometry>
                <mesh filename="package://fertig/meshes/boxes.STL" />
            </geometry>
            <material name="">
                <color rgba="0.792156862745098 0.819607843137255 0.933333333333333 1" />
            </material>
        </visual>
        <collision>
            <origin xyz="0 0 0" rpy="0 0 0" />
            <geometry>
                <mesh filename="package://fertig/meshes/boxes.STL" />
            </geometry>
        </collision>
    </link>
    <joint name="boxes" type="fixed">
        <origin xyz="-0.719999999999999 0 0" rpy="0 0 0" />
        <parent link="world_link" />
        <child link="boxes" />
        <axis xyz="0 0 0" />
    </joint>
    <link name="knickarm_sockel">
        <inertial>
            <origin xyz="0.170000000008435 0.170000000008423 0.222253510440883" rpy="0 0 0" />
            <mass value="33.1902670854663" />
            <inertia ixx="0.969242711259421" ixy="7.47530158539784E-17" ixz="3.18870986264805E-11" iyy="0.96924271125942" iyz="3.18429869567209E-11" izz="0.397801462826718" />
        </inertial>
        <visual>
            <origin xyz="0 0 0" rpy="0 0 0" />
            <geometry>
                <mesh filename="package://fertig/meshes/knickarm_sockel.STL" />
            </geometry>
            <material name="">
                <color rgba="0.792156862745098 0.819607843137255 0.933333333333333 1" />
            </material>
        </visual>
        <collision>
            <origin xyz="0 0 0" rpy="0 0 0" />
            <geometry>
                <mesh filename="package://fertig/meshes/knickarm_sockel.STL" />
            </geometry>
        </collision>
    </link>
    <joint name="knickarm_sockel" type="fixed">
        <origin xyz="-0.545000000000015 2.693 -0.0199999999999988" rpy="0 0 0" />
        <parent link="world_link" />
        <child link="knickarm_sockel" />
        <axis xyz="0 0 0" />
    </joint>
    <link name="knick_base_link">
        <inertial>
            <origin xyz="5.55111512312578E-17 0 0.0831886098900351" rpy="0 0 0" />
            <mass value="6.13619139503562" />
            <inertia ixx="0.0358502952817987" ixy="1.24550570065579E-17" ixz="2.77322340586902E-18" iyy="0.0358502952817986" iyz="-3.01901372422557E-17" izz="0.0367184665537518" />
        </inertial>
        <visual>
            <origin xyz="0 0 0" rpy="0 0 0" />
            <geometry>
                <mesh filename="package://fertig/meshes/knick_base_link.STL" />
            </geometry>
            <material name="">
                <color rgba="0.501960784313725 0.501960784313725 0.501960784313725 1" />
            </material>
        </visual>
        <collision>
            <origin xyz="0 0 0" rpy="0 0 0" />
            <geometry>
                <mesh filename="package://fertig/meshes/knick_base_link.STL" />
            </geometry>
        </collision>
    </link>
    <joint name="knick_base_joint" type="fixed">
        <origin xyz="0.17 0.17 0.5" rpy="0 0 0" />
        <parent link="knickarm_sockel" />
        <child link="knick_base_link" />
        <axis xyz="0 0 0" />
    </joint>
    <link name="knick_link1">
        <inertial>
            <origin xyz="2.39423167756603E-05 0.0010240364179781 0.0522188072773566" rpy="0 0 0" />
            <mass value="1.51482515033565" />
            <inertia ixx="0.00708081683843717" ixy="-3.18073734412148E-05" ixz="-4.89552296678815E-07" iyy="0.00592760506272545" iyz="-3.16730446962948E-05" izz="0.0078063707821689" />
        </inertial>
        <visual>
            <origin xyz="0 0 0" rpy="0 0 0" />
            <geometry>
                <mesh filename="package://fertig/meshes/knick_link1.STL" />
            </geometry>
            <material name="">
                <color rgba="0.501960784313725 0.501960784313725 0.501960784313725 1" />
            </material>
        </visual>
        <collision>
            <origin xyz="0 0 0" rpy="0 0 0" />
            <geometry>
                <mesh filename="package://fertig/meshes/knick_link1.STL" />
            </geometry>
        </collision>
    </link>
    <joint name="knick_joint1" type="revolute">
        <origin xyz="0 0 0.18" rpy="0 0 0" />
        <parent link="knick_base_link" />
        <child link="knick_link1" />
        <axis xyz="0 0 1" />
        <limit lower="-3" upper="3" effort="0" velocity="0" />
    </joint>
    <link name="knick_link2">
        <inertial>
            <origin xyz="-0.0211617911626847 0.122623282821051 0.0617606178597971" rpy="0 0 0" />
            <mass value="2.94963721988334" />
            <inertia ixx="0.0336504890440506" ixy="0.00481091926517843" ixz="0.000200207164863983" iyy="0.00659891776889086" iyz="-0.00116004183551096" izz="0.0330918774402128" />
        </inertial>
        <visual>
            <origin xyz="0 0 0" rpy="0 0 0" />
            <geometry>
                <mesh filename="package://fertig/meshes/knick_link2.STL" />
            </geometry>
            <material name="">
                <color rgba="0.501960784313725 0.501960784313725 0.501960784313725 1" />
            </material>
        </visual>
        <collision>
            <origin xyz="0 0 0" rpy="0 0 0" />
            <geometry>
                <mesh filename="package://fertig/meshes/knick_link2.STL" />
            </geometry>
        </collision>
    </link>
    <joint name="knick_joint2" type="revolute">
        <origin xyz="-0.00165 -0.059977 0.13" rpy="1.5708 0 3.1141" />
        <parent link="knick_link1" />
        <child link="knick_link2" />
        <axis xyz="0 0 1" />
        <limit lower="-3" upper="3" effort="0" velocity="0" />
    </joint>
    <link name="knick_link3">
        <inertial>
            <origin xyz="0.0385442987200408 0.0215860684868259 0.0473648804877551" rpy="0 0 0" />
            <mass value="0.491452097756812" />
            <inertia ixx="0.00108430376684807" ixy="-0.000668814930747442" ixz="-5.20576415471871E-05" iyy="0.00190416250100467" iyz="-2.9145455005666E-05" izz="0.00208350057092462" />
        </inertial>
        <visual>
            <origin xyz="0 0 0" rpy="0 0 0" />
            <geometry>
                <mesh filename="package://fertig/meshes/knick_link3.STL" />
            </geometry>
            <material name="">
                <color rgba="0.501960784313725 0.501960784313725 0.501960784313725 1" />
            </material>
        </visual>
        <collision>
            <origin xyz="0 0 0" rpy="0 0 0" />
            <geometry>
                <mesh filename="package://fertig/meshes/knick_link3.STL" />
            </geometry>
        </collision>
    </link>
    <joint name="knick_joint3" type="revolute">
        <origin xyz="-0.051008 0.29563 0.02" rpy="0 0 0" />
        <parent link="knick_link2" />
        <child link="knick_link3" />
        <axis xyz="0 0 1" />
        <limit lower="-3" upper="3" effort="0" velocity="0" />
    </joint>
    <link name="knick_link4">
        <inertial>
            <origin xyz="-0.0048361 -0.00090776 0.089602" rpy="0 0 0" />
            <mass value="0.98805" />
            <inertia ixx="0.0040653" ixy="-0.00041131" ixz="6.4537E-06" iyy="0.0047977" iyz="2.895E-06" izz="0.0018287" />
        </inertial>
        <visual>
            <origin xyz="0 0 0" rpy="0 0 0" />
            <geometry>
                <mesh filename="package://fertig/meshes/knick_link4.STL" />
            </geometry>
            <material name="">
                <color rgba="0.50196 0.50196 0.50196 1" />
            </material>
        </visual>
        <collision>
            <origin xyz="0 0 0" rpy="0 0 0" />
            <geometry>
                <mesh filename="package://fertig/meshes/knick_link4.STL" />
            </geometry>
        </collision>
    </link>
    <joint name="knick_joint4" type="revolute">
        <origin xyz="0.13566 0.074989 0.052879" rpy="0.5106 1.5708 0" />
        <parent link="knick_link3" />
        <child link="knick_link4" />
        <axis xyz="0 0 1" />
        <limit lower="-3" upper="3" effort="0" velocity="0" />
    </joint>
    <link name="knick_link5">
        <inertial>
            <origin xyz="0.025465 0.037495 0.049535" rpy="0 0 0" />
            <mass value="0.31824" />
            <inertia ixx="0.00094962" ixy="-0.000318" ixz="8.623E-05" iyy="0.00069697" iyz="0.00012766" izz="0.0010627" />
        </inertial>
        <visual>
            <origin xyz="0 0 0" rpy="0 0 0" />
            <geometry>
                <mesh filename="package://fertig/meshes/knick_link5.STL" />
            </geometry>
            <material name="">
                <color rgba="0.50196 0.50196 0.50196 1" />
            </material>
        </visual>
        <collision>
            <origin xyz="0 0 0" rpy="0 0 0" />
            <geometry>
                <mesh filename="package://fertig/meshes/knick_link5.STL" />
            </geometry>
        </collision>
    </link>
    <joint name="knick_joint5" type="revolute">
        <origin xyz="0.035397 0.01714 0.185" rpy="1.5708 -1.0202 -1.1491" />
        <parent link="knick_link4" />
        <child link="knick_link5" />
        <axis xyz="0 0 1" />
        <limit lower="-3" upper="3" effort="0" velocity="0" />
    </joint>
    <link name="knick_link6">
        <inertial>
            <origin xyz="-1.08396188771565E-05 2.16971466906468E-05 0.0451830670747682" rpy="0 0 0" />
            <mass value="0.226630428770624" />
            <inertia ixx="0.00013486308565457" ixy="-1.59026842796774E-05" ixz="-4.18492980674188E-09" iyy="0.000158728575069332" iyz="8.45820003110474E-09" izz="0.000104997312802144" />
        </inertial>
        <visual>
            <origin xyz="0 0 0" rpy="0 0 0" />
            <geometry>
                <mesh filename="package://fertig/meshes/knick_link6.STL" />
            </geometry>
            <material name="">
                <color rgba="0.792156862745098 0.819607843137255 0.933333333333333 1" />
            </material>
        </visual>
        <collision>
            <origin xyz="0 0 0" rpy="0 0 0" />
            <geometry>
                <mesh filename="package://fertig/meshes/knick_link6.STL" />
            </geometry>
        </collision>
    </link>
    <joint name="knick_joint6" type="revolute">
        <origin xyz="0.07015 0.10346 0.039" rpy="-1.5708 0.97279 -0.59583" />
        <parent link="knick_link5" />
        <child link="knick_link6" />
        <axis xyz="0 0 1" />
        <limit lower="3" upper="3" effort="0" velocity="0" />
    </joint>
    <link name="tisch">
        <inertial>
            <origin xyz="0 0 0" rpy="0 0 0" />
            <mass value="0" />
            <inertia ixx="0" ixy="0" ixz="0" iyy="0" iyz="0" izz="0" />
        </inertial>
        <visual>
            <origin xyz="0 0 0" rpy="0 0 0" />
            <geometry>
                <mesh filename="package://fertig/meshes/tisch.STL" />
            </geometry>
            <material name="">
                <color rgba="1 1 1 1" />
            </material>
        </visual>
        <collision>
            <origin xyz="0 0 0" rpy="0 0 0" />
            <geometry>
                <mesh filename="package://fertig/meshes/tisch.STL" />
            </geometry>
        </collision>
    </link>
    <joint name="tisch" type="fixed">
        <origin xyz="-1.07 2.523 -0.0199999999999989" rpy="1.5707963267949 -1.5707963267949 0" />
        <parent link="world_link" />
        <child link="tisch" />
        <axis xyz="0 0 0" />
    </joint>
    <transmission name="trans_scara_joint_1">
        <type>transmission_interface/SimpleTransmission</type>
        <joint name="scara_joint_1">
            <hardwareInterface>hardware_interface/PositionJointInterface</hardwareInterface>
        </joint>
        <actuator name="scara_joint_1_motor">
            <hardwareInterface>hardware_interface/PositionJointInterface</hardwareInterface>
            <mechanicalReduction>1</mechanicalReduction>
        </actuator>
    </transmission>
    <transmission name="trans_scara_joint_2">
        <type>transmission_interface/SimpleTransmission</type>
        <joint name="scara_joint_2">
            <hardwareInterface>hardware_interface/PositionJointInterface</hardwareInterface>
        </joint>
        <actuator name="scara_joint_2_motor">
            <hardwareInterface>hardware_interface/PositionJointInterface</hardwareInterface>
            <mechanicalReduction>1</mechanicalReduction>
        </actuator>
    </transmission>
    <transmission name="trans_scara_joint_3">
        <type>transmission_interface/SimpleTransmission</type>
        <joint name="scara_joint_3">
            <hardwareInterface>hardware_interface/PositionJointInterface</hardwareInterface>
        </joint>
        <actuator name="scara_joint_3_motor">
            <hardwareInterface>hardware_interface/PositionJointInterface</hardwareInterface>
            <mechanicalReduction>1</mechanicalReduction>
        </actuator>
    </transmission>
    <transmission name="trans_knick_joint1">
        <type>transmission_interface/SimpleTransmission</type>
        <joint name="knick_joint1">
            <hardwareInterface>hardware_interface/PositionJointInterface</hardwareInterface>
        </joint>
        <actuator name="knick_joint1_motor">
            <hardwareInterface>hardware_interface/PositionJointInterface</hardwareInterface>
            <mechanicalReduction>1</mechanicalReduction>
        </actuator>
    </transmission>
    <transmission name="trans_knick_joint2">
        <type>transmission_interface/SimpleTransmission</type>
        <joint name="knick_joint2">
            <hardwareInterface>hardware_interface/PositionJointInterface</hardwareInterface>
        </joint>
        <actuator name="knick_joint2_motor">
            <hardwareInterface>hardware_interface/PositionJointInterface</hardwareInterface>
            <mechanicalReduction>1</mechanicalReduction>
        </actuator>
    </transmission>
    <transmission name="trans_knick_joint3">
        <type>transmission_interface/SimpleTransmission</type>
        <joint name="knick_joint3">
            <hardwareInterface>hardware_interface/PositionJointInterface</hardwareInterface>
        </joint>
        <actuator name="knick_joint3_motor">
            <hardwareInterface>hardware_interface/PositionJointInterface</hardwareInterface>
            <mechanicalReduction>1</mechanicalReduction>
        </actuator>
    </transmission>
    <transmission name="trans_knick_joint4">
        <type>transmission_interface/SimpleTransmission</type>
        <joint name="knick_joint4">
            <hardwareInterface>hardware_interface/PositionJointInterface</hardwareInterface>
        </joint>
        <actuator name="knick_joint4_motor">
            <hardwareInterface>hardware_interface/PositionJointInterface</hardwareInterface>
            <mechanicalReduction>1</mechanicalReduction>
        </actuator>
    </transmission>
    <transmission name="trans_knick_joint5">
        <type>transmission_interface/SimpleTransmission</type>
        <joint name="knick_joint5">
            <hardwareInterface>hardware_interface/PositionJointInterface</hardwareInterface>
        </joint>
        <actuator name="knick_joint5_motor">
            <hardwareInterface>hardware_interface/PositionJointInterface</hardwareInterface>
            <mechanicalReduction>1</mechanicalReduction>
        </actuator>
    </transmission>
    <transmission name="trans_knick_joint6">
        <type>transmission_interface/SimpleTransmission</type>
        <joint name="knick_joint6">
            <hardwareInterface>hardware_interface/PositionJointInterface</hardwareInterface>
        </joint>
        <actuator name="knick_joint6_motor">
            <hardwareInterface>hardware_interface/PositionJointInterface</hardwareInterface>
            <mechanicalReduction>1</mechanicalReduction>
        </actuator>
    </transmission>
    <gazebo>
        <plugin name="gazebo_ros_control" filename="libgazebo_ros_control.so">
            <robotNamespace>/</robotNamespace>
        </plugin>
    </gazebo>
</robot>

